package nex.world.biome.feature;

import net.minecraft.block.state.IBlockState;
import net.minecraft.init.Blocks;
import net.minecraft.tileentity.TileEntity;
import net.minecraft.tileentity.TileEntityChest;
import net.minecraft.tileentity.TileEntityMobSpawner;
import net.minecraft.util.math.BlockPos;
import net.minecraft.world.World;
import net.minecraft.world.storage.loot.LootTableList;
import nex.api.NetherExAPI;
import nex.api.biome.feature.BiomeFeature;

import java.util.Random;

public class BiomeFeatureDungeon extends BiomeFeature
{
    public final IBlockState target;

    public BiomeFeatureDungeon(int genAttemptsIn, int minYIn, int maxYIn, IBlockState targetIn)
    {
        super(genAttemptsIn, minYIn, maxYIn);

        target = targetIn;
    }

    @Override
    public boolean generate(World world, Random rand, BlockPos pos)
    {
        int i = rand.nextInt(33);

        if(world.getBlockState(pos) == target && i == 0)
        {
            world.setBlockState(pos.add(0, -1, 0), Blocks.NETHER_BRICK.getDefaultState(), 2);
            world.setBlockState(pos.add(1, -1, 0), Blocks.NETHER_BRICK.getDefaultState(), 2);
            world.setBlockState(pos.add(2, -1, 0), Blocks.NETHER_BRICK.getDefaultState(), 2);
            world.setBlockState(pos.add(3, -1, 0), Blocks.AIR.getDefaultState(), 2);
            world.setBlockState(pos.add(4, -1, 0), Blocks.AIR.getDefaultState(), 2);
            world.setBlockState(pos.add(5, -1, 0), Blocks.AIR.getDefaultState(), 2);
            world.setBlockState(pos.add(6, -1, 0), Blocks.AIR.getDefaultState(), 2);
            world.setBlockState(pos.add(7, -1, 0), Blocks.AIR.getDefaultState(), 2);
            world.setBlockState(pos.add(8, -1, 0), Blocks.AIR.getDefaultState(), 2);
            world.setBlockState(pos.add(9, -1, 0), Blocks.AIR.getDefaultState(), 2);
            world.setBlockState(pos.add(10, -1, 0), Blocks.NETHER_BRICK.getDefaultState(), 2);
            world.setBlockState(pos.add(11, -1, 0), Blocks.NETHER_BRICK.getDefaultState(), 2);
            world.setBlockState(pos.add(12, -1, 0), Blocks.NETHER_BRICK.getDefaultState(), 2);
            world.setBlockState(pos.add(0, -1, 1), Blocks.NETHER_BRICK.getDefaultState(), 2);
            world.setBlockState(pos.add(1, -1, 1), Blocks.NETHER_BRICK.getDefaultState(), 2);
            world.setBlockState(pos.add(2, -1, 1), Blocks.NETHER_BRICK.getDefaultState(), 2);
            world.setBlockState(pos.add(3, -1, 1), Blocks.NETHER_BRICK.getDefaultState(), 2);
            world.setBlockState(pos.add(4, -1, 1), Blocks.NETHER_BRICK.getDefaultState(), 2);
            world.setBlockState(pos.add(5, -1, 1), Blocks.NETHER_BRICK.getDefaultState(), 2);
            world.setBlockState(pos.add(6, -1, 1), Blocks.NETHER_BRICK.getDefaultState(), 2);
            world.setBlockState(pos.add(7, -1, 1), Blocks.NETHER_BRICK.getDefaultState(), 2);
            world.setBlockState(pos.add(8, -1, 1), Blocks.NETHER_BRICK.getDefaultState(), 2);
            world.setBlockState(pos.add(9, -1, 1), Blocks.NETHER_BRICK.getDefaultState(), 2);
            world.setBlockState(pos.add(10, -1, 1), Blocks.NETHER_BRICK.getDefaultState(), 2);
            world.setBlockState(pos.add(11, -1, 1), Blocks.NETHER_BRICK.getDefaultState(), 2);
            world.setBlockState(pos.add(12, -1, 1), Blocks.NETHER_BRICK.getDefaultState(), 2);
            world.setBlockState(pos.add(0, -1, 2), Blocks.NETHER_BRICK.getDefaultState(), 2);
            world.setBlockState(pos.add(1, -1, 2), Blocks.NETHER_BRICK.getDefaultState(), 2);
            world.setBlockState(pos.add(2, -1, 2), Blocks.NETHER_BRICK.getDefaultState(), 2);
            world.setBlockState(pos.add(3, -1, 2), Blocks.NETHER_BRICK.getDefaultState(), 2);
            world.setBlockState(pos.add(4, -1, 2), Blocks.NETHER_BRICK.getDefaultState(), 2);
            world.setBlockState(pos.add(5, -1, 2), Blocks.NETHER_BRICK.getDefaultState(), 2);
            world.setBlockState(pos.add(6, -1, 2), Blocks.NETHER_BRICK.getDefaultState(), 2);
            world.setBlockState(pos.add(7, -1, 2), Blocks.NETHER_BRICK.getDefaultState(), 2);
            world.setBlockState(pos.add(8, -1, 2), Blocks.NETHER_BRICK.getDefaultState(), 2);
            world.setBlockState(pos.add(9, -1, 2), Blocks.NETHER_BRICK.getDefaultState(), 2);
            world.setBlockState(pos.add(10, -1, 2), Blocks.NETHER_BRICK.getDefaultState(), 2);
            world.setBlockState(pos.add(11, -1, 2), Blocks.NETHER_BRICK.getDefaultState(), 2);
            world.setBlockState(pos.add(12, -1, 2), Blocks.NETHER_BRICK.getDefaultState(), 2);
            world.setBlockState(pos.add(0, -1, 3), Blocks.AIR.getDefaultState(), 2);
            world.setBlockState(pos.add(1, -1, 3), Blocks.NETHER_BRICK.getDefaultState(), 2);
            world.setBlockState(pos.add(2, -1, 3), Blocks.NETHER_BRICK.getDefaultState(), 2);
            world.setBlockState(pos.add(3, -1, 3), Blocks.NETHER_BRICK.getDefaultState(), 2);
            world.setBlockState(pos.add(4, -1, 3), Blocks.NETHER_BRICK.getDefaultState(), 2);
            world.setBlockState(pos.add(5, -1, 3), Blocks.NETHER_BRICK.getDefaultState(), 2);
            world.setBlockState(pos.add(6, -1, 3), Blocks.NETHER_BRICK.getDefaultState(), 2);
            world.setBlockState(pos.add(7, -1, 3), Blocks.NETHER_BRICK.getDefaultState(), 2);
            world.setBlockState(pos.add(8, -1, 3), Blocks.NETHER_BRICK.getDefaultState(), 2);
            world.setBlockState(pos.add(9, -1, 3), Blocks.NETHER_BRICK.getDefaultState(), 2);
            world.setBlockState(pos.add(10, -1, 3), Blocks.NETHER_BRICK.getDefaultState(), 2);
            world.setBlockState(pos.add(11, -1, 3), Blocks.NETHER_BRICK.getDefaultState(), 2);
            world.setBlockState(pos.add(12, -1, 3), Blocks.AIR.getDefaultState(), 2);
            world.setBlockState(pos.add(0, -1, 4), Blocks.AIR.getDefaultState(), 2);
            world.setBlockState(pos.add(1, -1, 4), Blocks.NETHER_BRICK.getDefaultState(), 2);
            world.setBlockState(pos.add(2, -1, 4), Blocks.NETHER_BRICK.getDefaultState(), 2);
            world.setBlockState(pos.add(3, -1, 4), Blocks.NETHER_BRICK.getDefaultState(), 2);
            world.setBlockState(pos.add(4, -1, 4), Blocks.NETHER_BRICK.getDefaultState(), 2);
            world.setBlockState(pos.add(5, -1, 4), Blocks.NETHER_BRICK.getDefaultState(), 2);
            world.setBlockState(pos.add(6, -1, 4), Blocks.NETHER_BRICK.getDefaultState(), 2);
            world.setBlockState(pos.add(7, -1, 4), Blocks.NETHER_BRICK.getDefaultState(), 2);
            world.setBlockState(pos.add(8, -1, 4), Blocks.NETHER_BRICK.getDefaultState(), 2);
            world.setBlockState(pos.add(9, -1, 4), Blocks.NETHER_BRICK.getDefaultState(), 2);
            world.setBlockState(pos.add(10, -1, 4), Blocks.NETHER_BRICK.getDefaultState(), 2);
            world.setBlockState(pos.add(11, -1, 4), Blocks.NETHER_BRICK.getDefaultState(), 2);
            world.setBlockState(pos.add(12, -1, 4), Blocks.AIR.getDefaultState(), 2);
            world.setBlockState(pos.add(0, -1, 5), Blocks.AIR.getDefaultState(), 2);
            world.setBlockState(pos.add(1, -1, 5), Blocks.NETHER_BRICK.getDefaultState(), 2);
            world.setBlockState(pos.add(2, -1, 5), Blocks.NETHER_BRICK.getDefaultState(), 2);
            world.setBlockState(pos.add(3, -1, 5), Blocks.NETHER_BRICK.getDefaultState(), 2);
            world.setBlockState(pos.add(4, -1, 5), Blocks.NETHER_BRICK.getDefaultState(), 2);
            world.setBlockState(pos.add(5, -1, 5), Blocks.NETHER_BRICK.getDefaultState(), 2);
            world.setBlockState(pos.add(6, -1, 5), Blocks.NETHER_BRICK.getDefaultState(), 2);
            world.setBlockState(pos.add(7, -1, 5), Blocks.NETHER_BRICK.getDefaultState(), 2);
            world.setBlockState(pos.add(8, -1, 5), Blocks.NETHER_BRICK.getDefaultState(), 2);
            world.setBlockState(pos.add(9, -1, 5), Blocks.NETHER_BRICK.getDefaultState(), 2);
            world.setBlockState(pos.add(10, -1, 5), Blocks.NETHER_BRICK.getDefaultState(), 2);
            world.setBlockState(pos.add(11, -1, 5), Blocks.NETHER_BRICK.getDefaultState(), 2);
            world.setBlockState(pos.add(12, -1, 5), Blocks.AIR.getDefaultState(), 2);
            world.setBlockState(pos.add(0, -1, 6), Blocks.AIR.getDefaultState(), 2);
            world.setBlockState(pos.add(1, -1, 6), Blocks.NETHER_BRICK.getDefaultState(), 2);
            world.setBlockState(pos.add(2, -1, 6), Blocks.NETHER_BRICK.getDefaultState(), 2);
            world.setBlockState(pos.add(3, -1, 6), Blocks.NETHER_BRICK.getDefaultState(), 2);
            world.setBlockState(pos.add(4, -1, 6), Blocks.NETHER_BRICK.getDefaultState(), 2);
            world.setBlockState(pos.add(5, -1, 6), Blocks.NETHER_BRICK.getDefaultState(), 2);
            world.setBlockState(pos.add(6, -1, 6), Blocks.OBSIDIAN.getDefaultState(), 2);
            world.setBlockState(pos.add(7, -1, 6), Blocks.NETHER_BRICK.getDefaultState(), 2);
            world.setBlockState(pos.add(8, -1, 6), Blocks.NETHER_BRICK.getDefaultState(), 2);
            world.setBlockState(pos.add(9, -1, 6), Blocks.NETHER_BRICK.getDefaultState(), 2);
            world.setBlockState(pos.add(10, -1, 6), Blocks.NETHER_BRICK.getDefaultState(), 2);
            world.setBlockState(pos.add(11, -1, 6), Blocks.NETHER_BRICK.getDefaultState(), 2);
            world.setBlockState(pos.add(12, -1, 6), Blocks.AIR.getDefaultState(), 2);
            world.setBlockState(pos.add(0, -1, 7), Blocks.AIR.getDefaultState(), 2);
            world.setBlockState(pos.add(1, -1, 7), Blocks.NETHER_BRICK.getDefaultState(), 2);
            world.setBlockState(pos.add(2, -1, 7), Blocks.NETHER_BRICK.getDefaultState(), 2);
            world.setBlockState(pos.add(3, -1, 7), Blocks.NETHER_BRICK.getDefaultState(), 2);
            world.setBlockState(pos.add(4, -1, 7), Blocks.NETHER_BRICK.getDefaultState(), 2);
            world.setBlockState(pos.add(5, -1, 7), Blocks.NETHER_BRICK.getDefaultState(), 2);
            world.setBlockState(pos.add(6, -1, 7), Blocks.NETHER_BRICK.getDefaultState(), 2);
            world.setBlockState(pos.add(7, -1, 7), Blocks.NETHER_BRICK.getDefaultState(), 2);
            world.setBlockState(pos.add(8, -1, 7), Blocks.NETHER_BRICK.getDefaultState(), 2);
            world.setBlockState(pos.add(9, -1, 7), Blocks.NETHER_BRICK.getDefaultState(), 2);
            world.setBlockState(pos.add(10, -1, 7), Blocks.NETHER_BRICK.getDefaultState(), 2);
            world.setBlockState(pos.add(11, -1, 7), Blocks.NETHER_BRICK.getDefaultState(), 2);
            world.setBlockState(pos.add(12, -1, 7), Blocks.AIR.getDefaultState(), 2);
            world.setBlockState(pos.add(0, -1, 8), Blocks.AIR.getDefaultState(), 2);
            world.setBlockState(pos.add(1, -1, 8), Blocks.NETHER_BRICK.getDefaultState(), 2);
            world.setBlockState(pos.add(2, -1, 8), Blocks.NETHER_BRICK.getDefaultState(), 2);
            world.setBlockState(pos.add(3, -1, 8), Blocks.NETHER_BRICK.getDefaultState(), 2);
            world.setBlockState(pos.add(4, -1, 8), Blocks.NETHER_BRICK.getDefaultState(), 2);
            world.setBlockState(pos.add(5, -1, 8), Blocks.NETHER_BRICK.getDefaultState(), 2);
            world.setBlockState(pos.add(6, -1, 8), Blocks.NETHER_BRICK.getDefaultState(), 2);
            world.setBlockState(pos.add(7, -1, 8), Blocks.NETHER_BRICK.getDefaultState(), 2);
            world.setBlockState(pos.add(8, -1, 8), Blocks.NETHER_BRICK.getDefaultState(), 2);
            world.setBlockState(pos.add(9, -1, 8), Blocks.NETHER_BRICK.getDefaultState(), 2);
            world.setBlockState(pos.add(10, -1, 8), Blocks.NETHER_BRICK.getDefaultState(), 2);
            world.setBlockState(pos.add(11, -1, 8), Blocks.NETHER_BRICK.getDefaultState(), 2);
            world.setBlockState(pos.add(12, -1, 8), Blocks.AIR.getDefaultState(), 2);
            world.setBlockState(pos.add(0, -1, 9), Blocks.AIR.getDefaultState(), 2);
            world.setBlockState(pos.add(1, -1, 9), Blocks.NETHER_BRICK.getDefaultState(), 2);
            world.setBlockState(pos.add(2, -1, 9), Blocks.NETHER_BRICK.getDefaultState(), 2);
            world.setBlockState(pos.add(3, -1, 9), Blocks.NETHER_BRICK.getDefaultState(), 2);
            world.setBlockState(pos.add(4, -1, 9), Blocks.NETHER_BRICK.getDefaultState(), 2);
            world.setBlockState(pos.add(5, -1, 9), Blocks.NETHER_BRICK.getDefaultState(), 2);
            world.setBlockState(pos.add(6, -1, 9), Blocks.NETHER_BRICK.getDefaultState(), 2);
            world.setBlockState(pos.add(7, -1, 9), Blocks.NETHER_BRICK.getDefaultState(), 2);
            world.setBlockState(pos.add(8, -1, 9), Blocks.NETHER_BRICK.getDefaultState(), 2);
            world.setBlockState(pos.add(9, -1, 9), Blocks.NETHER_BRICK.getDefaultState(), 2);
            world.setBlockState(pos.add(10, -1, 9), Blocks.NETHER_BRICK.getDefaultState(), 2);
            world.setBlockState(pos.add(11, -1, 9), Blocks.NETHER_BRICK.getDefaultState(), 2);
            world.setBlockState(pos.add(12, -1, 9), Blocks.AIR.getDefaultState(), 2);
            world.setBlockState(pos.add(0, -1, 10), Blocks.NETHER_BRICK.getDefaultState(), 2);
            world.setBlockState(pos.add(1, -1, 10), Blocks.NETHER_BRICK.getDefaultState(), 2);
            world.setBlockState(pos.add(2, -1, 10), Blocks.NETHER_BRICK.getDefaultState(), 2);
            world.setBlockState(pos.add(3, -1, 10), Blocks.NETHER_BRICK.getDefaultState(), 2);
            world.setBlockState(pos.add(4, -1, 10), Blocks.NETHER_BRICK.getDefaultState(), 2);
            world.setBlockState(pos.add(5, -1, 10), Blocks.NETHER_BRICK.getDefaultState(), 2);
            world.setBlockState(pos.add(6, -1, 10), Blocks.NETHER_BRICK.getDefaultState(), 2);
            world.setBlockState(pos.add(7, -1, 10), Blocks.NETHER_BRICK.getDefaultState(), 2);
            world.setBlockState(pos.add(8, -1, 10), Blocks.NETHER_BRICK.getDefaultState(), 2);
            world.setBlockState(pos.add(9, -1, 10), Blocks.NETHER_BRICK.getDefaultState(), 2);
            world.setBlockState(pos.add(10, -1, 10), Blocks.NETHER_BRICK.getDefaultState(), 2);
            world.setBlockState(pos.add(11, -1, 10), Blocks.NETHER_BRICK.getDefaultState(), 2);
            world.setBlockState(pos.add(12, -1, 10), Blocks.NETHER_BRICK.getDefaultState(), 2);
            world.setBlockState(pos.add(0, -1, 11), Blocks.NETHER_BRICK.getDefaultState(), 2);
            world.setBlockState(pos.add(1, -1, 11), Blocks.NETHER_BRICK.getDefaultState(), 2);
            world.setBlockState(pos.add(2, -1, 11), Blocks.NETHER_BRICK.getDefaultState(), 2);
            world.setBlockState(pos.add(3, -1, 11), Blocks.NETHER_BRICK.getDefaultState(), 2);
            world.setBlockState(pos.add(4, -1, 11), Blocks.NETHER_BRICK.getDefaultState(), 2);
            world.setBlockState(pos.add(5, -1, 11), Blocks.NETHER_BRICK.getDefaultState(), 2);
            world.setBlockState(pos.add(6, -1, 11), Blocks.NETHER_BRICK.getDefaultState(), 2);
            world.setBlockState(pos.add(7, -1, 11), Blocks.NETHER_BRICK.getDefaultState(), 2);
            world.setBlockState(pos.add(8, -1, 11), Blocks.NETHER_BRICK.getDefaultState(), 2);
            world.setBlockState(pos.add(9, -1, 11), Blocks.NETHER_BRICK.getDefaultState(), 2);
            world.setBlockState(pos.add(10, -1, 11), Blocks.NETHER_BRICK.getDefaultState(), 2);
            world.setBlockState(pos.add(11, -1, 11), Blocks.NETHER_BRICK.getDefaultState(), 2);
            world.setBlockState(pos.add(12, -1, 11), Blocks.NETHER_BRICK.getDefaultState(), 2);
            world.setBlockState(pos.add(0, -1, 12), Blocks.NETHER_BRICK.getDefaultState(), 2);
            world.setBlockState(pos.add(1, -1, 12), Blocks.NETHER_BRICK.getDefaultState(), 2);
            world.setBlockState(pos.add(2, -1, 12), Blocks.NETHER_BRICK.getDefaultState(), 2);
            world.setBlockState(pos.add(3, -1, 12), Blocks.AIR.getDefaultState(), 2);
            world.setBlockState(pos.add(4, -1, 12), Blocks.AIR.getDefaultState(), 2);
            world.setBlockState(pos.add(5, -1, 12), Blocks.AIR.getDefaultState(), 2);
            world.setBlockState(pos.add(6, -1, 12), Blocks.AIR.getDefaultState(), 2);
            world.setBlockState(pos.add(7, -1, 12), Blocks.AIR.getDefaultState(), 2);
            world.setBlockState(pos.add(8, -1, 12), Blocks.AIR.getDefaultState(), 2);
            world.setBlockState(pos.add(9, -1, 12), Blocks.AIR.getDefaultState(), 2);
            world.setBlockState(pos.add(10, -1, 12), Blocks.NETHER_BRICK.getDefaultState(), 2);
            world.setBlockState(pos.add(11, -1, 12), Blocks.NETHER_BRICK.getDefaultState(), 2);
            world.setBlockState(pos.add(12, -1, 12), Blocks.NETHER_BRICK.getDefaultState(), 2);
            world.setBlockState(pos.add(0, 0, 0), Blocks.NETHER_BRICK.getDefaultState(), 2);
            world.setBlockState(pos.add(1, 0, 0), Blocks.NETHER_BRICK.getDefaultState(), 2);
            world.setBlockState(pos.add(2, 0, 0), Blocks.NETHER_BRICK.getDefaultState(), 2);
            world.setBlockState(pos.add(3, 0, 0), Blocks.AIR.getDefaultState(), 2);
            world.setBlockState(pos.add(4, 0, 0), Blocks.AIR.getDefaultState(), 2);
            world.setBlockState(pos.add(5, 0, 0), Blocks.AIR.getDefaultState(), 2);
            world.setBlockState(pos.add(6, 0, 0), Blocks.AIR.getDefaultState(), 2);
            world.setBlockState(pos.add(7, 0, 0), Blocks.AIR.getDefaultState(), 2);
            world.setBlockState(pos.add(8, 0, 0), Blocks.AIR.getDefaultState(), 2);
            world.setBlockState(pos.add(9, 0, 0), Blocks.AIR.getDefaultState(), 2);
            world.setBlockState(pos.add(10, 0, 0), Blocks.NETHER_BRICK.getDefaultState(), 2);
            world.setBlockState(pos.add(11, 0, 0), Blocks.NETHER_BRICK.getDefaultState(), 2);
            world.setBlockState(pos.add(12, 0, 0), Blocks.NETHER_BRICK.getDefaultState(), 2);
            world.setBlockState(pos.add(0, 0, 1), Blocks.NETHER_BRICK.getDefaultState(), 2);
            world.setBlockState(pos.add(1, 0, 1), Blocks.NETHER_BRICK.getDefaultState(), 2);
            world.setBlockState(pos.add(2, 0, 1), Blocks.NETHER_BRICK.getDefaultState(), 2);
            world.setBlockState(pos.add(3, 0, 1), Blocks.NETHER_BRICK.getDefaultState(), 2);
            world.setBlockState(pos.add(4, 0, 1), Blocks.NETHER_BRICK.getDefaultState(), 2);
            world.setBlockState(pos.add(5, 0, 1), Blocks.NETHER_BRICK.getDefaultState(), 2);
            world.setBlockState(pos.add(6, 0, 1), Blocks.NETHER_BRICK.getDefaultState(), 2);
            world.setBlockState(pos.add(7, 0, 1), Blocks.NETHER_BRICK.getDefaultState(), 2);
            world.setBlockState(pos.add(8, 0, 1), Blocks.NETHER_BRICK.getDefaultState(), 2);
            world.setBlockState(pos.add(9, 0, 1), Blocks.NETHER_BRICK.getDefaultState(), 2);
            world.setBlockState(pos.add(10, 0, 1), Blocks.NETHER_BRICK.getDefaultState(), 2);
            world.setBlockState(pos.add(11, 0, 1), Blocks.NETHER_BRICK.getDefaultState(), 2);
            world.setBlockState(pos.add(12, 0, 1), Blocks.NETHER_BRICK.getDefaultState(), 2);
            world.setBlockState(pos.add(0, 0, 2), Blocks.NETHER_BRICK.getDefaultState(), 2);
            world.setBlockState(pos.add(1, 0, 2), Blocks.NETHER_BRICK.getDefaultState(), 2);
            world.setBlockState(pos.add(2, 0, 2), Blocks.NETHER_BRICK.getDefaultState(), 2);
            world.setBlockState(pos.add(3, 0, 2), Blocks.AIR.getDefaultState(), 2);
            world.setBlockState(pos.add(4, 0, 2), Blocks.AIR.getDefaultState(), 2);
            world.setBlockState(pos.add(5, 0, 2), Blocks.AIR.getDefaultState(), 2);
            world.setBlockState(pos.add(6, 0, 2), Blocks.AIR.getDefaultState(), 2);
            world.setBlockState(pos.add(7, 0, 2), Blocks.AIR.getDefaultState(), 2);
            world.setBlockState(pos.add(8, 0, 2), Blocks.AIR.getDefaultState(), 2);
            world.setBlockState(pos.add(9, 0, 2), Blocks.AIR.getDefaultState(), 2);
            world.setBlockState(pos.add(10, 0, 2), Blocks.NETHER_BRICK.getDefaultState(), 2);
            world.setBlockState(pos.add(11, 0, 2), Blocks.NETHER_BRICK.getDefaultState(), 2);
            world.setBlockState(pos.add(12, 0, 2), Blocks.NETHER_BRICK.getDefaultState(), 2);
            world.setBlockState(pos.add(0, 0, 3), Blocks.AIR.getDefaultState(), 2);
            world.setBlockState(pos.add(1, 0, 3), Blocks.NETHER_BRICK.getDefaultState(), 2);
            world.setBlockState(pos.add(2, 0, 3), Blocks.AIR.getDefaultState(), 2);
            world.setBlockState(pos.add(3, 0, 3), Blocks.AIR.getDefaultState(), 2);
            world.setBlockState(pos.add(4, 0, 3), Blocks.AIR.getDefaultState(), 2);
            world.setBlockState(pos.add(5, 0, 3), Blocks.AIR.getDefaultState(), 2);
            world.setBlockState(pos.add(6, 0, 3), Blocks.AIR.getDefaultState(), 2);
            world.setBlockState(pos.add(7, 0, 3), Blocks.AIR.getDefaultState(), 2);
            world.setBlockState(pos.add(8, 0, 3), Blocks.AIR.getDefaultState(), 2);
            world.setBlockState(pos.add(9, 0, 3), Blocks.AIR.getDefaultState(), 2);
            world.setBlockState(pos.add(10, 0, 3), Blocks.AIR.getDefaultState(), 2);
            world.setBlockState(pos.add(11, 0, 3), Blocks.NETHER_BRICK.getDefaultState(), 2);
            world.setBlockState(pos.add(12, 0, 3), Blocks.AIR.getDefaultState(), 2);
            world.setBlockState(pos.add(0, 0, 4), Blocks.AIR.getDefaultState(), 2);
            world.setBlockState(pos.add(1, 0, 4), Blocks.NETHER_BRICK.getDefaultState(), 2);
            world.setBlockState(pos.add(2, 0, 4), Blocks.AIR.getDefaultState(), 2);
            world.setBlockState(pos.add(3, 0, 4), Blocks.AIR.getDefaultState(), 2);
            world.setBlockState(pos.add(4, 0, 4), Blocks.AIR.getDefaultState(), 2);
            world.setBlockState(pos.add(5, 0, 4), Blocks.AIR.getDefaultState(), 2);
            world.setBlockState(pos.add(6, 0, 4), Blocks.AIR.getDefaultState(), 2);
            world.setBlockState(pos.add(7, 0, 4), Blocks.AIR.getDefaultState(), 2);
            world.setBlockState(pos.add(8, 0, 4), Blocks.AIR.getDefaultState(), 2);
            world.setBlockState(pos.add(9, 0, 4), Blocks.AIR.getDefaultState(), 2);
            world.setBlockState(pos.add(10, 0, 4), Blocks.AIR.getDefaultState(), 2);
            world.setBlockState(pos.add(11, 0, 4), Blocks.NETHER_BRICK.getDefaultState(), 2);
            world.setBlockState(pos.add(12, 0, 4), Blocks.AIR.getDefaultState(), 2);
            world.setBlockState(pos.add(0, 0, 5), Blocks.AIR.getDefaultState(), 2);
            world.setBlockState(pos.add(1, 0, 5), Blocks.NETHER_BRICK.getDefaultState(), 2);
            world.setBlockState(pos.add(2, 0, 5), Blocks.AIR.getDefaultState(), 2);
            world.setBlockState(pos.add(3, 0, 5), Blocks.AIR.getDefaultState(), 2);
            world.setBlockState(pos.add(4, 0, 5), Blocks.AIR.getDefaultState(), 2);
            world.setBlockState(pos.add(5, 0, 5), Blocks.AIR.getDefaultState(), 2);
            world.setBlockState(pos.add(6, 0, 5), Blocks.OBSIDIAN.getDefaultState(), 2);
            world.setBlockState(pos.add(7, 0, 5), Blocks.AIR.getDefaultState(), 2);
            world.setBlockState(pos.add(8, 0, 5), Blocks.AIR.getDefaultState(), 2);
            world.setBlockState(pos.add(9, 0, 5), Blocks.AIR.getDefaultState(), 2);
            world.setBlockState(pos.add(10, 0, 5), Blocks.AIR.getDefaultState(), 2);
            world.setBlockState(pos.add(11, 0, 5), Blocks.NETHER_BRICK.getDefaultState(), 2);
            world.setBlockState(pos.add(12, 0, 5), Blocks.AIR.getDefaultState(), 2);
            world.setBlockState(pos.add(0, 0, 6), Blocks.AIR.getDefaultState(), 2);
            world.setBlockState(pos.add(1, 0, 6), Blocks.NETHER_BRICK.getDefaultState(), 2);
            world.setBlockState(pos.add(2, 0, 6), Blocks.AIR.getDefaultState(), 2);
            world.setBlockState(pos.add(3, 0, 6), Blocks.AIR.getDefaultState(), 2);
            world.setBlockState(pos.add(4, 0, 6), Blocks.AIR.getDefaultState(), 2);
            world.setBlockState(pos.add(5, 0, 6), Blocks.OBSIDIAN.getDefaultState(), 2);
            world.setBlockState(pos.add(6, 0, 6), Blocks.MOB_SPAWNER.getDefaultState(), 2);

            TileEntity spawner = world.getTileEntity(pos.add(6, 0, 6));

            if(spawner instanceof TileEntityMobSpawner)
            {
                ((TileEntityMobSpawner) spawner).getSpawnerBaseLogic().setEntityName(pickRandomSpawner(rand));
            }

            world.setBlockState(pos.add(7, 0, 6), Blocks.OBSIDIAN.getDefaultState(), 2);
            world.setBlockState(pos.add(8, 0, 6), Blocks.AIR.getDefaultState(), 2);
            world.setBlockState(pos.add(9, 0, 6), Blocks.AIR.getDefaultState(), 2);
            world.setBlockState(pos.add(10, 0, 6), Blocks.AIR.getDefaultState(), 2);
            world.setBlockState(pos.add(11, 0, 6), Blocks.NETHER_BRICK.getDefaultState(), 2);
            world.setBlockState(pos.add(12, 0, 6), Blocks.AIR.getDefaultState(), 2);
            world.setBlockState(pos.add(0, 0, 7), Blocks.AIR.getDefaultState(), 2);
            world.setBlockState(pos.add(1, 0, 7), Blocks.NETHER_BRICK.getDefaultState(), 2);
            world.setBlockState(pos.add(2, 0, 7), Blocks.AIR.getDefaultState(), 2);
            world.setBlockState(pos.add(3, 0, 7), Blocks.AIR.getDefaultState(), 2);
            world.setBlockState(pos.add(4, 0, 7), Blocks.AIR.getDefaultState(), 2);
            world.setBlockState(pos.add(5, 0, 7), Blocks.AIR.getDefaultState(), 2);
            world.setBlockState(pos.add(6, 0, 7), Blocks.OBSIDIAN.getDefaultState(), 2);
            world.setBlockState(pos.add(7, 0, 7), Blocks.AIR.getDefaultState(), 2);
            world.setBlockState(pos.add(8, 0, 7), Blocks.AIR.getDefaultState(), 2);
            world.setBlockState(pos.add(9, 0, 7), Blocks.AIR.getDefaultState(), 2);
            world.setBlockState(pos.add(10, 0, 7), Blocks.AIR.getDefaultState(), 2);
            world.setBlockState(pos.add(11, 0, 7), Blocks.NETHER_BRICK.getDefaultState(), 2);
            world.setBlockState(pos.add(12, 0, 7), Blocks.AIR.getDefaultState(), 2);
            world.setBlockState(pos.add(0, 0, 8), Blocks.AIR.getDefaultState(), 2);
            world.setBlockState(pos.add(1, 0, 8), Blocks.NETHER_BRICK.getDefaultState(), 2);
            world.setBlockState(pos.add(2, 0, 8), Blocks.AIR.getDefaultState(), 2);
            world.setBlockState(pos.add(3, 0, 8), Blocks.AIR.getDefaultState(), 2);
            world.setBlockState(pos.add(4, 0, 8), Blocks.AIR.getDefaultState(), 2);
            world.setBlockState(pos.add(5, 0, 8), Blocks.AIR.getDefaultState(), 2);
            world.setBlockState(pos.add(6, 0, 8), Blocks.AIR.getDefaultState(), 2);
            world.setBlockState(pos.add(7, 0, 8), Blocks.AIR.getDefaultState(), 2);
            world.setBlockState(pos.add(8, 0, 8), Blocks.AIR.getDefaultState(), 2);
            world.setBlockState(pos.add(9, 0, 8), Blocks.AIR.getDefaultState(), 2);
            world.setBlockState(pos.add(10, 0, 8), Blocks.AIR.getDefaultState(), 2);
            world.setBlockState(pos.add(11, 0, 8), Blocks.NETHER_BRICK.getDefaultState(), 2);
            world.setBlockState(pos.add(12, 0, 8), Blocks.AIR.getDefaultState(), 2);
            world.setBlockState(pos.add(0, 0, 9), Blocks.AIR.getDefaultState(), 2);
            world.setBlockState(pos.add(1, 0, 9), Blocks.NETHER_BRICK.getDefaultState(), 2);
            world.setBlockState(pos.add(2, 0, 9), Blocks.AIR.getDefaultState(), 2);
            world.setBlockState(pos.add(3, 0, 9), Blocks.AIR.getDefaultState(), 2);
            world.setBlockState(pos.add(4, 0, 9), Blocks.AIR.getDefaultState(), 2);
            world.setBlockState(pos.add(5, 0, 9), Blocks.AIR.getDefaultState(), 2);
            world.setBlockState(pos.add(6, 0, 9), Blocks.AIR.getDefaultState(), 2);
            world.setBlockState(pos.add(7, 0, 9), Blocks.AIR.getDefaultState(), 2);
            world.setBlockState(pos.add(8, 0, 9), Blocks.AIR.getDefaultState(), 2);
            world.setBlockState(pos.add(9, 0, 9), Blocks.AIR.getDefaultState(), 2);
            world.setBlockState(pos.add(10, 0, 9), Blocks.AIR.getDefaultState(), 2);
            world.setBlockState(pos.add(11, 0, 9), Blocks.NETHER_BRICK.getDefaultState(), 2);
            world.setBlockState(pos.add(12, 0, 9), Blocks.AIR.getDefaultState(), 2);
            world.setBlockState(pos.add(0, 0, 10), Blocks.NETHER_BRICK.getDefaultState(), 2);
            world.setBlockState(pos.add(1, 0, 10), Blocks.NETHER_BRICK.getDefaultState(), 2);
            world.setBlockState(pos.add(2, 0, 10), Blocks.NETHER_BRICK.getDefaultState(), 2);
            world.setBlockState(pos.add(3, 0, 10), Blocks.AIR.getDefaultState(), 2);
            world.setBlockState(pos.add(4, 0, 10), Blocks.AIR.getDefaultState(), 2);
            world.setBlockState(pos.add(5, 0, 10), Blocks.AIR.getDefaultState(), 2);
            world.setBlockState(pos.add(6, 0, 10), Blocks.AIR.getDefaultState(), 2);
            world.setBlockState(pos.add(7, 0, 10), Blocks.AIR.getDefaultState(), 2);
            world.setBlockState(pos.add(8, 0, 10), Blocks.AIR.getDefaultState(), 2);
            world.setBlockState(pos.add(9, 0, 10), Blocks.AIR.getDefaultState(), 2);
            world.setBlockState(pos.add(10, 0, 10), Blocks.NETHER_BRICK.getDefaultState(), 2);
            world.setBlockState(pos.add(11, 0, 10), Blocks.NETHER_BRICK.getDefaultState(), 2);
            world.setBlockState(pos.add(12, 0, 10), Blocks.NETHER_BRICK.getDefaultState(), 2);
            world.setBlockState(pos.add(0, 0, 11), Blocks.NETHER_BRICK.getDefaultState(), 2);
            world.setBlockState(pos.add(1, 0, 11), Blocks.NETHER_BRICK.getDefaultState(), 2);
            world.setBlockState(pos.add(2, 0, 11), Blocks.NETHER_BRICK.getDefaultState(), 2);
            world.setBlockState(pos.add(3, 0, 11), Blocks.NETHER_BRICK.getDefaultState(), 2);
            world.setBlockState(pos.add(4, 0, 11), Blocks.NETHER_BRICK.getDefaultState(), 2);
            world.setBlockState(pos.add(5, 0, 11), Blocks.NETHER_BRICK.getDefaultState(), 2);
            world.setBlockState(pos.add(6, 0, 11), Blocks.NETHER_BRICK.getDefaultState(), 2);
            world.setBlockState(pos.add(7, 0, 11), Blocks.NETHER_BRICK.getDefaultState(), 2);
            world.setBlockState(pos.add(8, 0, 11), Blocks.NETHER_BRICK.getDefaultState(), 2);
            world.setBlockState(pos.add(9, 0, 11), Blocks.NETHER_BRICK.getDefaultState(), 2);
            world.setBlockState(pos.add(10, 0, 11), Blocks.NETHER_BRICK.getDefaultState(), 2);
            world.setBlockState(pos.add(11, 0, 11), Blocks.NETHER_BRICK.getDefaultState(), 2);
            world.setBlockState(pos.add(12, 0, 11), Blocks.NETHER_BRICK.getDefaultState(), 2);
            world.setBlockState(pos.add(0, 0, 12), Blocks.NETHER_BRICK.getDefaultState(), 2);
            world.setBlockState(pos.add(1, 0, 12), Blocks.NETHER_BRICK.getDefaultState(), 2);
            world.setBlockState(pos.add(2, 0, 12), Blocks.NETHER_BRICK.getDefaultState(), 2);
            world.setBlockState(pos.add(3, 0, 12), Blocks.AIR.getDefaultState(), 2);
            world.setBlockState(pos.add(4, 0, 12), Blocks.AIR.getDefaultState(), 2);
            world.setBlockState(pos.add(5, 0, 12), Blocks.AIR.getDefaultState(), 2);
            world.setBlockState(pos.add(6, 0, 12), Blocks.AIR.getDefaultState(), 2);
            world.setBlockState(pos.add(7, 0, 12), Blocks.AIR.getDefaultState(), 2);
            world.setBlockState(pos.add(8, 0, 12), Blocks.AIR.getDefaultState(), 2);
            world.setBlockState(pos.add(9, 0, 12), Blocks.AIR.getDefaultState(), 2);
            world.setBlockState(pos.add(10, 0, 12), Blocks.NETHER_BRICK.getDefaultState(), 2);
            world.setBlockState(pos.add(11, 0, 12), Blocks.NETHER_BRICK.getDefaultState(), 2);
            world.setBlockState(pos.add(12, 0, 12), Blocks.NETHER_BRICK.getDefaultState(), 2);
            world.setBlockState(pos.add(0, 1, 0), Blocks.NETHER_BRICK.getDefaultState(), 2);
            world.setBlockState(pos.add(1, 1, 0), Blocks.NETHER_BRICK.getDefaultState(), 2);
            world.setBlockState(pos.add(2, 1, 0), Blocks.NETHER_BRICK.getDefaultState(), 2);
            world.setBlockState(pos.add(3, 1, 0), Blocks.AIR.getDefaultState(), 2);
            world.setBlockState(pos.add(4, 1, 0), Blocks.AIR.getDefaultState(), 2);
            world.setBlockState(pos.add(5, 1, 0), Blocks.AIR.getDefaultState(), 2);
            world.setBlockState(pos.add(6, 1, 0), Blocks.AIR.getDefaultState(), 2);
            world.setBlockState(pos.add(7, 1, 0), Blocks.AIR.getDefaultState(), 2);
            world.setBlockState(pos.add(8, 1, 0), Blocks.AIR.getDefaultState(), 2);
            world.setBlockState(pos.add(9, 1, 0), Blocks.AIR.getDefaultState(), 2);
            world.setBlockState(pos.add(10, 1, 0), Blocks.NETHER_BRICK.getDefaultState(), 2);
            world.setBlockState(pos.add(11, 1, 0), Blocks.NETHER_BRICK.getDefaultState(), 2);
            world.setBlockState(pos.add(12, 1, 0), Blocks.NETHER_BRICK.getDefaultState(), 2);
            world.setBlockState(pos.add(0, 1, 1), Blocks.NETHER_BRICK.getDefaultState(), 2);
            world.setBlockState(pos.add(1, 1, 1), Blocks.NETHER_BRICK.getDefaultState(), 2);
            world.setBlockState(pos.add(2, 1, 1), Blocks.NETHER_BRICK.getDefaultState(), 2);
            world.setBlockState(pos.add(3, 1, 1), Blocks.NETHER_BRICK.getDefaultState(), 2);
            world.setBlockState(pos.add(4, 1, 1), Blocks.NETHER_BRICK.getDefaultState(), 2);
            world.setBlockState(pos.add(5, 1, 1), Blocks.NETHER_BRICK.getDefaultState(), 2);
            world.setBlockState(pos.add(6, 1, 1), Blocks.NETHER_BRICK.getDefaultState(), 2);
            world.setBlockState(pos.add(7, 1, 1), Blocks.NETHER_BRICK.getDefaultState(), 2);
            world.setBlockState(pos.add(8, 1, 1), Blocks.NETHER_BRICK.getDefaultState(), 2);
            world.setBlockState(pos.add(9, 1, 1), Blocks.NETHER_BRICK.getDefaultState(), 2);
            world.setBlockState(pos.add(10, 1, 1), Blocks.NETHER_BRICK.getDefaultState(), 2);
            world.setBlockState(pos.add(11, 1, 1), Blocks.NETHER_BRICK.getDefaultState(), 2);
            world.setBlockState(pos.add(12, 1, 1), Blocks.NETHER_BRICK.getDefaultState(), 2);
            world.setBlockState(pos.add(0, 1, 2), Blocks.NETHER_BRICK.getDefaultState(), 2);
            world.setBlockState(pos.add(1, 1, 2), Blocks.NETHER_BRICK.getDefaultState(), 2);
            world.setBlockState(pos.add(2, 1, 2), Blocks.NETHER_BRICK.getDefaultState(), 2);
            world.setBlockState(pos.add(3, 1, 2), Blocks.AIR.getDefaultState(), 2);
            world.setBlockState(pos.add(4, 1, 2), Blocks.AIR.getDefaultState(), 2);
            world.setBlockState(pos.add(5, 1, 2), Blocks.AIR.getDefaultState(), 2);
            world.setBlockState(pos.add(6, 1, 2), Blocks.AIR.getDefaultState(), 2);
            world.setBlockState(pos.add(7, 1, 2), Blocks.AIR.getDefaultState(), 2);
            world.setBlockState(pos.add(8, 1, 2), Blocks.AIR.getDefaultState(), 2);
            world.setBlockState(pos.add(9, 1, 2), Blocks.AIR.getDefaultState(), 2);
            world.setBlockState(pos.add(10, 1, 2), Blocks.NETHER_BRICK.getDefaultState(), 2);
            world.setBlockState(pos.add(11, 1, 2), Blocks.NETHER_BRICK.getDefaultState(), 2);
            world.setBlockState(pos.add(12, 1, 2), Blocks.NETHER_BRICK.getDefaultState(), 2);
            world.setBlockState(pos.add(0, 1, 3), Blocks.AIR.getDefaultState(), 2);
            world.setBlockState(pos.add(1, 1, 3), Blocks.NETHER_BRICK.getDefaultState(), 2);
            world.setBlockState(pos.add(2, 1, 3), Blocks.AIR.getDefaultState(), 2);
            world.setBlockState(pos.add(3, 1, 3), Blocks.AIR.getDefaultState(), 2);
            world.setBlockState(pos.add(4, 1, 3), Blocks.AIR.getDefaultState(), 2);
            world.setBlockState(pos.add(5, 1, 3), Blocks.AIR.getDefaultState(), 2);
            world.setBlockState(pos.add(6, 1, 3), Blocks.AIR.getDefaultState(), 2);
            world.setBlockState(pos.add(7, 1, 3), Blocks.AIR.getDefaultState(), 2);
            world.setBlockState(pos.add(8, 1, 3), Blocks.AIR.getDefaultState(), 2);
            world.setBlockState(pos.add(9, 1, 3), Blocks.AIR.getDefaultState(), 2);
            world.setBlockState(pos.add(10, 1, 3), Blocks.AIR.getDefaultState(), 2);
            world.setBlockState(pos.add(11, 1, 3), Blocks.NETHER_BRICK.getDefaultState(), 2);
            world.setBlockState(pos.add(12, 1, 3), Blocks.AIR.getDefaultState(), 2);
            world.setBlockState(pos.add(0, 1, 4), Blocks.AIR.getDefaultState(), 2);
            world.setBlockState(pos.add(1, 1, 4), Blocks.NETHER_BRICK.getDefaultState(), 2);
            world.setBlockState(pos.add(2, 1, 4), Blocks.AIR.getDefaultState(), 2);
            world.setBlockState(pos.add(3, 1, 4), Blocks.AIR.getDefaultState(), 2);
            world.setBlockState(pos.add(4, 1, 4), Blocks.AIR.getDefaultState(), 2);
            world.setBlockState(pos.add(5, 1, 4), Blocks.AIR.getDefaultState(), 2);
            world.setBlockState(pos.add(6, 1, 4), Blocks.AIR.getDefaultState(), 2);
            world.setBlockState(pos.add(7, 1, 4), Blocks.AIR.getDefaultState(), 2);
            world.setBlockState(pos.add(8, 1, 4), Blocks.AIR.getDefaultState(), 2);
            world.setBlockState(pos.add(9, 1, 4), Blocks.AIR.getDefaultState(), 2);
            world.setBlockState(pos.add(10, 1, 4), Blocks.AIR.getDefaultState(), 2);
            world.setBlockState(pos.add(11, 1, 4), Blocks.NETHER_BRICK.getDefaultState(), 2);
            world.setBlockState(pos.add(12, 1, 4), Blocks.AIR.getDefaultState(), 2);
            world.setBlockState(pos.add(0, 1, 5), Blocks.AIR.getDefaultState(), 2);
            world.setBlockState(pos.add(1, 1, 5), Blocks.NETHER_BRICK.getDefaultState(), 2);
            world.setBlockState(pos.add(2, 1, 5), Blocks.AIR.getDefaultState(), 2);
            world.setBlockState(pos.add(3, 1, 5), Blocks.AIR.getDefaultState(), 2);
            world.setBlockState(pos.add(4, 1, 5), Blocks.AIR.getDefaultState(), 2);
            world.setBlockState(pos.add(5, 1, 5), Blocks.AIR.getDefaultState(), 2);
            world.setBlockState(pos.add(6, 1, 5), Blocks.CHEST.getStateFromMeta(2), 3);

            TileEntity chest1 = world.getTileEntity(pos.add(6, 1, 5));

            if(chest1 instanceof TileEntityChest)
            {
                ((TileEntityChest) chest1).setLootTable(LootTableList.CHESTS_DESERT_PYRAMID, rand.nextLong());
            }

            world.setBlockState(pos.add(7, 1, 5), Blocks.AIR.getDefaultState(), 2);
            world.setBlockState(pos.add(8, 1, 5), Blocks.AIR.getDefaultState(), 2);
            world.setBlockState(pos.add(9, 1, 5), Blocks.AIR.getDefaultState(), 2);
            world.setBlockState(pos.add(10, 1, 5), Blocks.AIR.getDefaultState(), 2);
            world.setBlockState(pos.add(11, 1, 5), Blocks.NETHER_BRICK.getDefaultState(), 2);
            world.setBlockState(pos.add(12, 1, 5), Blocks.AIR.getDefaultState(), 2);
            world.setBlockState(pos.add(0, 1, 6), Blocks.AIR.getDefaultState(), 2);
            world.setBlockState(pos.add(1, 1, 6), Blocks.NETHER_BRICK.getDefaultState(), 2);
            world.setBlockState(pos.add(2, 1, 6), Blocks.AIR.getDefaultState(), 2);
            world.setBlockState(pos.add(3, 1, 6), Blocks.AIR.getDefaultState(), 2);
            world.setBlockState(pos.add(4, 1, 6), Blocks.AIR.getDefaultState(), 2);
            world.setBlockState(pos.add(5, 1, 6), Blocks.CHEST.getStateFromMeta(4), 3);

            TileEntity chest2 = world.getTileEntity(pos.add(5, 1, 6));

            if(chest2 instanceof TileEntityChest)
            {
                ((TileEntityChest) chest2).setLootTable(LootTableList.CHESTS_SIMPLE_DUNGEON, rand.nextLong());
            }

            world.setBlockState(pos.add(6, 1, 6), Blocks.OBSIDIAN.getDefaultState(), 2);
            world.setBlockState(pos.add(7, 1, 6), Blocks.CHEST.getStateFromMeta(5), 3);

            TileEntity chest3 = world.getTileEntity(pos.add(7, 1, 6));

            if(chest3 instanceof TileEntityChest)
            {
                ((TileEntityChest) chest3).setLootTable(LootTableList.CHESTS_END_CITY_TREASURE, rand.nextLong());
            }

            world.setBlockState(pos.add(8, 1, 6), Blocks.AIR.getDefaultState(), 2);
            world.setBlockState(pos.add(9, 1, 6), Blocks.AIR.getDefaultState(), 2);
            world.setBlockState(pos.add(10, 1, 6), Blocks.AIR.getDefaultState(), 2);
            world.setBlockState(pos.add(11, 1, 6), Blocks.NETHER_BRICK.getDefaultState(), 2);
            world.setBlockState(pos.add(12, 1, 6), Blocks.AIR.getDefaultState(), 2);
            world.setBlockState(pos.add(0, 1, 7), Blocks.AIR.getDefaultState(), 2);
            world.setBlockState(pos.add(1, 1, 7), Blocks.NETHER_BRICK.getDefaultState(), 2);
            world.setBlockState(pos.add(2, 1, 7), Blocks.AIR.getDefaultState(), 2);
            world.setBlockState(pos.add(3, 1, 7), Blocks.AIR.getDefaultState(), 2);
            world.setBlockState(pos.add(4, 1, 7), Blocks.AIR.getDefaultState(), 2);
            world.setBlockState(pos.add(5, 1, 7), Blocks.AIR.getDefaultState(), 2);
            world.setBlockState(pos.add(6, 1, 7), Blocks.CHEST.getStateFromMeta(3), 3);

            TileEntity chest4 = world.getTileEntity(pos.add(6, 1, 7));

            if(chest4 instanceof TileEntityChest)
            {
                ((TileEntityChest) chest4).setLootTable(LootTableList.CHESTS_JUNGLE_TEMPLE, rand.nextLong());
            }

            world.setBlockState(pos.add(7, 1, 7), Blocks.AIR.getDefaultState(), 2);
            world.setBlockState(pos.add(8, 1, 7), Blocks.AIR.getDefaultState(), 2);
            world.setBlockState(pos.add(9, 1, 7), Blocks.AIR.getDefaultState(), 2);
            world.setBlockState(pos.add(10, 1, 7), Blocks.AIR.getDefaultState(), 2);
            world.setBlockState(pos.add(11, 1, 7), Blocks.NETHER_BRICK.getDefaultState(), 2);
            world.setBlockState(pos.add(12, 1, 7), Blocks.AIR.getDefaultState(), 2);
            world.setBlockState(pos.add(0, 1, 8), Blocks.AIR.getDefaultState(), 2);
            world.setBlockState(pos.add(1, 1, 8), Blocks.NETHER_BRICK.getDefaultState(), 2);
            world.setBlockState(pos.add(2, 1, 8), Blocks.AIR.getDefaultState(), 2);
            world.setBlockState(pos.add(3, 1, 8), Blocks.AIR.getDefaultState(), 2);
            world.setBlockState(pos.add(4, 1, 8), Blocks.AIR.getDefaultState(), 2);
            world.setBlockState(pos.add(5, 1, 8), Blocks.AIR.getDefaultState(), 2);
            world.setBlockState(pos.add(6, 1, 8), Blocks.AIR.getDefaultState(), 2);
            world.setBlockState(pos.add(7, 1, 8), Blocks.AIR.getDefaultState(), 2);
            world.setBlockState(pos.add(8, 1, 8), Blocks.AIR.getDefaultState(), 2);
            world.setBlockState(pos.add(9, 1, 8), Blocks.AIR.getDefaultState(), 2);
            world.setBlockState(pos.add(10, 1, 8), Blocks.AIR.getDefaultState(), 2);
            world.setBlockState(pos.add(11, 1, 8), Blocks.NETHER_BRICK.getDefaultState(), 2);
            world.setBlockState(pos.add(12, 1, 8), Blocks.AIR.getDefaultState(), 2);
            world.setBlockState(pos.add(0, 1, 9), Blocks.AIR.getDefaultState(), 2);
            world.setBlockState(pos.add(1, 1, 9), Blocks.NETHER_BRICK.getDefaultState(), 2);
            world.setBlockState(pos.add(2, 1, 9), Blocks.AIR.getDefaultState(), 2);
            world.setBlockState(pos.add(3, 1, 9), Blocks.AIR.getDefaultState(), 2);
            world.setBlockState(pos.add(4, 1, 9), Blocks.AIR.getDefaultState(), 2);
            world.setBlockState(pos.add(5, 1, 9), Blocks.AIR.getDefaultState(), 2);
            world.setBlockState(pos.add(6, 1, 9), Blocks.AIR.getDefaultState(), 2);
            world.setBlockState(pos.add(7, 1, 9), Blocks.AIR.getDefaultState(), 2);
            world.setBlockState(pos.add(8, 1, 9), Blocks.AIR.getDefaultState(), 2);
            world.setBlockState(pos.add(9, 1, 9), Blocks.AIR.getDefaultState(), 2);
            world.setBlockState(pos.add(10, 1, 9), Blocks.AIR.getDefaultState(), 2);
            world.setBlockState(pos.add(11, 1, 9), Blocks.NETHER_BRICK.getDefaultState(), 2);
            world.setBlockState(pos.add(12, 1, 9), Blocks.AIR.getDefaultState(), 2);
            world.setBlockState(pos.add(0, 1, 10), Blocks.NETHER_BRICK.getDefaultState(), 2);
            world.setBlockState(pos.add(1, 1, 10), Blocks.NETHER_BRICK.getDefaultState(), 2);
            world.setBlockState(pos.add(2, 1, 10), Blocks.NETHER_BRICK.getDefaultState(), 2);
            world.setBlockState(pos.add(3, 1, 10), Blocks.AIR.getDefaultState(), 2);
            world.setBlockState(pos.add(4, 1, 10), Blocks.AIR.getDefaultState(), 2);
            world.setBlockState(pos.add(5, 1, 10), Blocks.AIR.getDefaultState(), 2);
            world.setBlockState(pos.add(6, 1, 10), Blocks.AIR.getDefaultState(), 2);
            world.setBlockState(pos.add(7, 1, 10), Blocks.AIR.getDefaultState(), 2);
            world.setBlockState(pos.add(8, 1, 10), Blocks.AIR.getDefaultState(), 2);
            world.setBlockState(pos.add(9, 1, 10), Blocks.AIR.getDefaultState(), 2);
            world.setBlockState(pos.add(10, 1, 10), Blocks.NETHER_BRICK.getDefaultState(), 2);
            world.setBlockState(pos.add(11, 1, 10), Blocks.NETHER_BRICK.getDefaultState(), 2);
            world.setBlockState(pos.add(12, 1, 10), Blocks.NETHER_BRICK.getDefaultState(), 2);
            world.setBlockState(pos.add(0, 1, 11), Blocks.NETHER_BRICK.getDefaultState(), 2);
            world.setBlockState(pos.add(1, 1, 11), Blocks.NETHER_BRICK.getDefaultState(), 2);
            world.setBlockState(pos.add(2, 1, 11), Blocks.NETHER_BRICK.getDefaultState(), 2);
            world.setBlockState(pos.add(3, 1, 11), Blocks.NETHER_BRICK.getDefaultState(), 2);
            world.setBlockState(pos.add(4, 1, 11), Blocks.NETHER_BRICK.getDefaultState(), 2);
            world.setBlockState(pos.add(5, 1, 11), Blocks.NETHER_BRICK.getDefaultState(), 2);
            world.setBlockState(pos.add(6, 1, 11), Blocks.NETHER_BRICK.getDefaultState(), 2);
            world.setBlockState(pos.add(7, 1, 11), Blocks.NETHER_BRICK.getDefaultState(), 2);
            world.setBlockState(pos.add(8, 1, 11), Blocks.NETHER_BRICK.getDefaultState(), 2);
            world.setBlockState(pos.add(9, 1, 11), Blocks.NETHER_BRICK.getDefaultState(), 2);
            world.setBlockState(pos.add(10, 1, 11), Blocks.NETHER_BRICK.getDefaultState(), 2);
            world.setBlockState(pos.add(11, 1, 11), Blocks.NETHER_BRICK.getDefaultState(), 2);
            world.setBlockState(pos.add(12, 1, 11), Blocks.NETHER_BRICK.getDefaultState(), 2);
            world.setBlockState(pos.add(0, 1, 12), Blocks.NETHER_BRICK.getDefaultState(), 2);
            world.setBlockState(pos.add(1, 1, 12), Blocks.NETHER_BRICK.getDefaultState(), 2);
            world.setBlockState(pos.add(2, 1, 12), Blocks.NETHER_BRICK.getDefaultState(), 2);
            world.setBlockState(pos.add(3, 1, 12), Blocks.AIR.getDefaultState(), 2);
            world.setBlockState(pos.add(4, 1, 12), Blocks.AIR.getDefaultState(), 2);
            world.setBlockState(pos.add(5, 1, 12), Blocks.AIR.getDefaultState(), 2);
            world.setBlockState(pos.add(6, 1, 12), Blocks.AIR.getDefaultState(), 2);
            world.setBlockState(pos.add(7, 1, 12), Blocks.AIR.getDefaultState(), 2);
            world.setBlockState(pos.add(8, 1, 12), Blocks.AIR.getDefaultState(), 2);
            world.setBlockState(pos.add(9, 1, 12), Blocks.AIR.getDefaultState(), 2);
            world.setBlockState(pos.add(10, 1, 12), Blocks.NETHER_BRICK.getDefaultState(), 2);
            world.setBlockState(pos.add(11, 1, 12), Blocks.NETHER_BRICK.getDefaultState(), 2);
            world.setBlockState(pos.add(12, 1, 12), Blocks.NETHER_BRICK.getDefaultState(), 2);
            world.setBlockState(pos.add(0, 2, 0), Blocks.NETHER_BRICK.getDefaultState(), 2);
            world.setBlockState(pos.add(1, 2, 0), Blocks.NETHER_BRICK.getDefaultState(), 2);
            world.setBlockState(pos.add(2, 2, 0), Blocks.NETHER_BRICK.getDefaultState(), 2);
            world.setBlockState(pos.add(3, 2, 0), Blocks.AIR.getDefaultState(), 2);
            world.setBlockState(pos.add(4, 2, 0), Blocks.AIR.getDefaultState(), 2);
            world.setBlockState(pos.add(5, 2, 0), Blocks.AIR.getDefaultState(), 2);
            world.setBlockState(pos.add(6, 2, 0), Blocks.AIR.getDefaultState(), 2);
            world.setBlockState(pos.add(7, 2, 0), Blocks.AIR.getDefaultState(), 2);
            world.setBlockState(pos.add(8, 2, 0), Blocks.AIR.getDefaultState(), 2);
            world.setBlockState(pos.add(9, 2, 0), Blocks.AIR.getDefaultState(), 2);
            world.setBlockState(pos.add(10, 2, 0), Blocks.NETHER_BRICK.getDefaultState(), 2);
            world.setBlockState(pos.add(11, 2, 0), Blocks.NETHER_BRICK.getDefaultState(), 2);
            world.setBlockState(pos.add(12, 2, 0), Blocks.NETHER_BRICK.getDefaultState(), 2);
            world.setBlockState(pos.add(0, 2, 1), Blocks.NETHER_BRICK.getDefaultState(), 2);
            world.setBlockState(pos.add(1, 2, 1), Blocks.NETHERRACK.getDefaultState(), 2);
            world.setBlockState(pos.add(2, 2, 1), Blocks.NETHER_BRICK.getDefaultState(), 2);
            world.setBlockState(pos.add(3, 2, 1), Blocks.NETHER_BRICK.getDefaultState(), 2);
            world.setBlockState(pos.add(4, 2, 1), Blocks.NETHER_BRICK.getDefaultState(), 2);
            world.setBlockState(pos.add(5, 2, 1), Blocks.NETHER_BRICK.getDefaultState(), 2);
            world.setBlockState(pos.add(6, 2, 1), Blocks.NETHER_BRICK.getDefaultState(), 2);
            world.setBlockState(pos.add(7, 2, 1), Blocks.NETHER_BRICK.getDefaultState(), 2);
            world.setBlockState(pos.add(8, 2, 1), Blocks.NETHER_BRICK.getDefaultState(), 2);
            world.setBlockState(pos.add(9, 2, 1), Blocks.NETHER_BRICK.getDefaultState(), 2);
            world.setBlockState(pos.add(10, 2, 1), Blocks.NETHER_BRICK.getDefaultState(), 2);
            world.setBlockState(pos.add(11, 2, 1), Blocks.NETHERRACK.getDefaultState(), 2);
            world.setBlockState(pos.add(12, 2, 1), Blocks.NETHER_BRICK.getDefaultState(), 2);
            world.setBlockState(pos.add(0, 2, 2), Blocks.NETHER_BRICK.getDefaultState(), 2);
            world.setBlockState(pos.add(1, 2, 2), Blocks.NETHER_BRICK.getDefaultState(), 2);
            world.setBlockState(pos.add(2, 2, 2), Blocks.NETHER_BRICK.getDefaultState(), 2);
            world.setBlockState(pos.add(3, 2, 2), Blocks.AIR.getDefaultState(), 2);
            world.setBlockState(pos.add(4, 2, 2), Blocks.AIR.getDefaultState(), 2);
            world.setBlockState(pos.add(5, 2, 2), Blocks.AIR.getDefaultState(), 2);
            world.setBlockState(pos.add(6, 2, 2), Blocks.AIR.getDefaultState(), 2);
            world.setBlockState(pos.add(7, 2, 2), Blocks.AIR.getDefaultState(), 2);
            world.setBlockState(pos.add(8, 2, 2), Blocks.AIR.getDefaultState(), 2);
            world.setBlockState(pos.add(9, 2, 2), Blocks.AIR.getDefaultState(), 2);
            world.setBlockState(pos.add(10, 2, 2), Blocks.NETHER_BRICK.getDefaultState(), 2);
            world.setBlockState(pos.add(11, 2, 2), Blocks.NETHER_BRICK.getDefaultState(), 2);
            world.setBlockState(pos.add(12, 2, 2), Blocks.NETHER_BRICK.getDefaultState(), 2);
            world.setBlockState(pos.add(0, 2, 3), Blocks.AIR.getDefaultState(), 2);
            world.setBlockState(pos.add(1, 2, 3), Blocks.NETHER_BRICK.getDefaultState(), 2);
            world.setBlockState(pos.add(2, 2, 3), Blocks.AIR.getDefaultState(), 2);
            world.setBlockState(pos.add(3, 2, 3), Blocks.AIR.getDefaultState(), 2);
            world.setBlockState(pos.add(4, 2, 3), Blocks.AIR.getDefaultState(), 2);
            world.setBlockState(pos.add(5, 2, 3), Blocks.AIR.getDefaultState(), 2);
            world.setBlockState(pos.add(6, 2, 3), Blocks.AIR.getDefaultState(), 2);
            world.setBlockState(pos.add(7, 2, 3), Blocks.AIR.getDefaultState(), 2);
            world.setBlockState(pos.add(8, 2, 3), Blocks.AIR.getDefaultState(), 2);
            world.setBlockState(pos.add(9, 2, 3), Blocks.AIR.getDefaultState(), 2);
            world.setBlockState(pos.add(10, 2, 3), Blocks.AIR.getDefaultState(), 2);
            world.setBlockState(pos.add(11, 2, 3), Blocks.NETHER_BRICK.getDefaultState(), 2);
            world.setBlockState(pos.add(12, 2, 3), Blocks.AIR.getDefaultState(), 2);
            world.setBlockState(pos.add(0, 2, 4), Blocks.AIR.getDefaultState(), 2);
            world.setBlockState(pos.add(1, 2, 4), Blocks.NETHER_BRICK.getDefaultState(), 2);
            world.setBlockState(pos.add(2, 2, 4), Blocks.AIR.getDefaultState(), 2);
            world.setBlockState(pos.add(3, 2, 4), Blocks.AIR.getDefaultState(), 2);
            world.setBlockState(pos.add(4, 2, 4), Blocks.AIR.getDefaultState(), 2);
            world.setBlockState(pos.add(5, 2, 4), Blocks.AIR.getDefaultState(), 2);
            world.setBlockState(pos.add(6, 2, 4), Blocks.AIR.getDefaultState(), 2);
            world.setBlockState(pos.add(7, 2, 4), Blocks.AIR.getDefaultState(), 2);
            world.setBlockState(pos.add(8, 2, 4), Blocks.AIR.getDefaultState(), 2);
            world.setBlockState(pos.add(9, 2, 4), Blocks.AIR.getDefaultState(), 2);
            world.setBlockState(pos.add(10, 2, 4), Blocks.AIR.getDefaultState(), 2);
            world.setBlockState(pos.add(11, 2, 4), Blocks.NETHER_BRICK.getDefaultState(), 2);
            world.setBlockState(pos.add(12, 2, 4), Blocks.AIR.getDefaultState(), 2);
            world.setBlockState(pos.add(0, 2, 5), Blocks.AIR.getDefaultState(), 2);
            world.setBlockState(pos.add(1, 2, 5), Blocks.NETHER_BRICK.getDefaultState(), 2);
            world.setBlockState(pos.add(2, 2, 5), Blocks.AIR.getDefaultState(), 2);
            world.setBlockState(pos.add(3, 2, 5), Blocks.AIR.getDefaultState(), 2);
            world.setBlockState(pos.add(4, 2, 5), Blocks.AIR.getDefaultState(), 2);
            world.setBlockState(pos.add(5, 2, 5), Blocks.AIR.getDefaultState(), 2);
            world.setBlockState(pos.add(6, 2, 5), Blocks.AIR.getDefaultState(), 2);
            world.setBlockState(pos.add(7, 2, 5), Blocks.AIR.getDefaultState(), 2);
            world.setBlockState(pos.add(8, 2, 5), Blocks.AIR.getDefaultState(), 2);
            world.setBlockState(pos.add(9, 2, 5), Blocks.AIR.getDefaultState(), 2);
            world.setBlockState(pos.add(10, 2, 5), Blocks.AIR.getDefaultState(), 2);
            world.setBlockState(pos.add(11, 2, 5), Blocks.NETHER_BRICK.getDefaultState(), 2);
            world.setBlockState(pos.add(12, 2, 5), Blocks.AIR.getDefaultState(), 2);
            world.setBlockState(pos.add(0, 2, 6), Blocks.AIR.getDefaultState(), 2);
            world.setBlockState(pos.add(1, 2, 6), Blocks.NETHER_BRICK.getDefaultState(), 2);
            world.setBlockState(pos.add(2, 2, 6), Blocks.AIR.getDefaultState(), 2);
            world.setBlockState(pos.add(3, 2, 6), Blocks.AIR.getDefaultState(), 2);
            world.setBlockState(pos.add(4, 2, 6), Blocks.AIR.getDefaultState(), 2);
            world.setBlockState(pos.add(5, 2, 6), Blocks.AIR.getDefaultState(), 2);
            world.setBlockState(pos.add(6, 2, 6), Blocks.AIR.getDefaultState(), 2);
            world.setBlockState(pos.add(7, 2, 6), Blocks.AIR.getDefaultState(), 2);
            world.setBlockState(pos.add(8, 2, 6), Blocks.AIR.getDefaultState(), 2);
            world.setBlockState(pos.add(9, 2, 6), Blocks.AIR.getDefaultState(), 2);
            world.setBlockState(pos.add(10, 2, 6), Blocks.AIR.getDefaultState(), 2);
            world.setBlockState(pos.add(11, 2, 6), Blocks.NETHER_BRICK.getDefaultState(), 2);
            world.setBlockState(pos.add(12, 2, 6), Blocks.AIR.getDefaultState(), 2);
            world.setBlockState(pos.add(0, 2, 7), Blocks.AIR.getDefaultState(), 2);
            world.setBlockState(pos.add(1, 2, 7), Blocks.NETHER_BRICK.getDefaultState(), 2);
            world.setBlockState(pos.add(2, 2, 7), Blocks.AIR.getDefaultState(), 2);
            world.setBlockState(pos.add(3, 2, 7), Blocks.AIR.getDefaultState(), 2);
            world.setBlockState(pos.add(4, 2, 7), Blocks.AIR.getDefaultState(), 2);
            world.setBlockState(pos.add(5, 2, 7), Blocks.AIR.getDefaultState(), 2);
            world.setBlockState(pos.add(6, 2, 7), Blocks.AIR.getDefaultState(), 2);
            world.setBlockState(pos.add(7, 2, 7), Blocks.AIR.getDefaultState(), 2);
            world.setBlockState(pos.add(8, 2, 7), Blocks.AIR.getDefaultState(), 2);
            world.setBlockState(pos.add(9, 2, 7), Blocks.AIR.getDefaultState(), 2);
            world.setBlockState(pos.add(10, 2, 7), Blocks.AIR.getDefaultState(), 2);
            world.setBlockState(pos.add(11, 2, 7), Blocks.NETHER_BRICK.getDefaultState(), 2);
            world.setBlockState(pos.add(12, 2, 7), Blocks.AIR.getDefaultState(), 2);
            world.setBlockState(pos.add(0, 2, 8), Blocks.AIR.getDefaultState(), 2);
            world.setBlockState(pos.add(1, 2, 8), Blocks.NETHER_BRICK.getDefaultState(), 2);
            world.setBlockState(pos.add(2, 2, 8), Blocks.AIR.getDefaultState(), 2);
            world.setBlockState(pos.add(3, 2, 8), Blocks.AIR.getDefaultState(), 2);
            world.setBlockState(pos.add(4, 2, 8), Blocks.AIR.getDefaultState(), 2);
            world.setBlockState(pos.add(5, 2, 8), Blocks.AIR.getDefaultState(), 2);
            world.setBlockState(pos.add(6, 2, 8), Blocks.AIR.getDefaultState(), 2);
            world.setBlockState(pos.add(7, 2, 8), Blocks.AIR.getDefaultState(), 2);
            world.setBlockState(pos.add(8, 2, 8), Blocks.AIR.getDefaultState(), 2);
            world.setBlockState(pos.add(9, 2, 8), Blocks.AIR.getDefaultState(), 2);
            world.setBlockState(pos.add(10, 2, 8), Blocks.AIR.getDefaultState(), 2);
            world.setBlockState(pos.add(11, 2, 8), Blocks.NETHER_BRICK.getDefaultState(), 2);
            world.setBlockState(pos.add(12, 2, 8), Blocks.AIR.getDefaultState(), 2);
            world.setBlockState(pos.add(0, 2, 9), Blocks.AIR.getDefaultState(), 2);
            world.setBlockState(pos.add(1, 2, 9), Blocks.NETHER_BRICK.getDefaultState(), 2);
            world.setBlockState(pos.add(2, 2, 9), Blocks.AIR.getDefaultState(), 2);
            world.setBlockState(pos.add(3, 2, 9), Blocks.AIR.getDefaultState(), 2);
            world.setBlockState(pos.add(4, 2, 9), Blocks.AIR.getDefaultState(), 2);
            world.setBlockState(pos.add(5, 2, 9), Blocks.AIR.getDefaultState(), 2);
            world.setBlockState(pos.add(6, 2, 9), Blocks.AIR.getDefaultState(), 2);
            world.setBlockState(pos.add(7, 2, 9), Blocks.AIR.getDefaultState(), 2);
            world.setBlockState(pos.add(8, 2, 9), Blocks.AIR.getDefaultState(), 2);
            world.setBlockState(pos.add(9, 2, 9), Blocks.AIR.getDefaultState(), 2);
            world.setBlockState(pos.add(10, 2, 9), Blocks.AIR.getDefaultState(), 2);
            world.setBlockState(pos.add(11, 2, 9), Blocks.NETHER_BRICK.getDefaultState(), 2);
            world.setBlockState(pos.add(12, 2, 9), Blocks.AIR.getDefaultState(), 2);
            world.setBlockState(pos.add(0, 2, 10), Blocks.NETHER_BRICK.getDefaultState(), 2);
            world.setBlockState(pos.add(1, 2, 10), Blocks.NETHER_BRICK.getDefaultState(), 2);
            world.setBlockState(pos.add(2, 2, 10), Blocks.NETHER_BRICK.getDefaultState(), 2);
            world.setBlockState(pos.add(3, 2, 10), Blocks.AIR.getDefaultState(), 2);
            world.setBlockState(pos.add(4, 2, 10), Blocks.AIR.getDefaultState(), 2);
            world.setBlockState(pos.add(5, 2, 10), Blocks.AIR.getDefaultState(), 2);
            world.setBlockState(pos.add(6, 2, 10), Blocks.AIR.getDefaultState(), 2);
            world.setBlockState(pos.add(7, 2, 10), Blocks.AIR.getDefaultState(), 2);
            world.setBlockState(pos.add(8, 2, 10), Blocks.AIR.getDefaultState(), 2);
            world.setBlockState(pos.add(9, 2, 10), Blocks.AIR.getDefaultState(), 2);
            world.setBlockState(pos.add(10, 2, 10), Blocks.NETHER_BRICK.getDefaultState(), 2);
            world.setBlockState(pos.add(11, 2, 10), Blocks.NETHER_BRICK.getDefaultState(), 2);
            world.setBlockState(pos.add(12, 2, 10), Blocks.NETHER_BRICK.getDefaultState(), 2);
            world.setBlockState(pos.add(0, 2, 11), Blocks.NETHER_BRICK.getDefaultState(), 2);
            world.setBlockState(pos.add(1, 2, 11), Blocks.NETHERRACK.getDefaultState(), 2);
            world.setBlockState(pos.add(2, 2, 11), Blocks.NETHER_BRICK.getDefaultState(), 2);
            world.setBlockState(pos.add(3, 2, 11), Blocks.NETHER_BRICK.getDefaultState(), 2);
            world.setBlockState(pos.add(4, 2, 11), Blocks.NETHER_BRICK.getDefaultState(), 2);
            world.setBlockState(pos.add(5, 2, 11), Blocks.NETHER_BRICK.getDefaultState(), 2);
            world.setBlockState(pos.add(6, 2, 11), Blocks.NETHER_BRICK.getDefaultState(), 2);
            world.setBlockState(pos.add(7, 2, 11), Blocks.NETHER_BRICK.getDefaultState(), 2);
            world.setBlockState(pos.add(8, 2, 11), Blocks.NETHER_BRICK.getDefaultState(), 2);
            world.setBlockState(pos.add(9, 2, 11), Blocks.NETHER_BRICK.getDefaultState(), 2);
            world.setBlockState(pos.add(10, 2, 11), Blocks.NETHER_BRICK.getDefaultState(), 2);
            world.setBlockState(pos.add(11, 2, 11), Blocks.NETHERRACK.getDefaultState(), 2);
            world.setBlockState(pos.add(12, 2, 11), Blocks.NETHER_BRICK.getDefaultState(), 2);
            world.setBlockState(pos.add(0, 2, 12), Blocks.NETHER_BRICK.getDefaultState(), 2);
            world.setBlockState(pos.add(1, 2, 12), Blocks.NETHER_BRICK.getDefaultState(), 2);
            world.setBlockState(pos.add(2, 2, 12), Blocks.NETHER_BRICK.getDefaultState(), 2);
            world.setBlockState(pos.add(3, 2, 12), Blocks.AIR.getDefaultState(), 2);
            world.setBlockState(pos.add(4, 2, 12), Blocks.AIR.getDefaultState(), 2);
            world.setBlockState(pos.add(5, 2, 12), Blocks.AIR.getDefaultState(), 2);
            world.setBlockState(pos.add(6, 2, 12), Blocks.AIR.getDefaultState(), 2);
            world.setBlockState(pos.add(7, 2, 12), Blocks.AIR.getDefaultState(), 2);
            world.setBlockState(pos.add(8, 2, 12), Blocks.AIR.getDefaultState(), 2);
            world.setBlockState(pos.add(9, 2, 12), Blocks.AIR.getDefaultState(), 2);
            world.setBlockState(pos.add(10, 2, 12), Blocks.NETHER_BRICK.getDefaultState(), 2);
            world.setBlockState(pos.add(11, 2, 12), Blocks.NETHER_BRICK.getDefaultState(), 2);
            world.setBlockState(pos.add(12, 2, 12), Blocks.NETHER_BRICK.getDefaultState(), 2);
            world.setBlockState(pos.add(0, 3, 0), Blocks.NETHER_BRICK_FENCE.getDefaultState(), 2);
            world.setBlockState(pos.add(1, 3, 0), Blocks.NETHER_BRICK_FENCE.getDefaultState(), 2);
            world.setBlockState(pos.add(2, 3, 0), Blocks.NETHER_BRICK_FENCE.getDefaultState(), 2);
            world.setBlockState(pos.add(3, 3, 0), Blocks.AIR.getDefaultState(), 2);
            world.setBlockState(pos.add(4, 3, 0), Blocks.AIR.getDefaultState(), 2);
            world.setBlockState(pos.add(5, 3, 0), Blocks.AIR.getDefaultState(), 2);
            world.setBlockState(pos.add(6, 3, 0), Blocks.AIR.getDefaultState(), 2);
            world.setBlockState(pos.add(7, 3, 0), Blocks.AIR.getDefaultState(), 2);
            world.setBlockState(pos.add(8, 3, 0), Blocks.AIR.getDefaultState(), 2);
            world.setBlockState(pos.add(9, 3, 0), Blocks.AIR.getDefaultState(), 2);
            world.setBlockState(pos.add(10, 3, 0), Blocks.NETHER_BRICK_FENCE.getDefaultState(), 2);
            world.setBlockState(pos.add(11, 3, 0), Blocks.NETHER_BRICK_FENCE.getDefaultState(), 2);
            world.setBlockState(pos.add(12, 3, 0), Blocks.NETHER_BRICK_FENCE.getDefaultState(), 2);
            world.setBlockState(pos.add(0, 3, 1), Blocks.NETHER_BRICK_FENCE.getDefaultState(), 2);
            world.setBlockState(pos.add(1, 3, 1), Blocks.FIRE.getDefaultState(), 2);
            world.setBlockState(pos.add(2, 3, 1), Blocks.NETHER_BRICK_FENCE.getDefaultState(), 2);
            world.setBlockState(pos.add(3, 3, 1), Blocks.NETHER_BRICK_FENCE.getDefaultState(), 2);
            world.setBlockState(pos.add(4, 3, 1), Blocks.NETHER_BRICK_FENCE.getDefaultState(), 2);
            world.setBlockState(pos.add(5, 3, 1), Blocks.NETHER_BRICK_FENCE.getDefaultState(), 2);
            world.setBlockState(pos.add(6, 3, 1), Blocks.NETHER_BRICK_FENCE.getDefaultState(), 2);
            world.setBlockState(pos.add(7, 3, 1), Blocks.NETHER_BRICK_FENCE.getDefaultState(), 2);
            world.setBlockState(pos.add(8, 3, 1), Blocks.NETHER_BRICK_FENCE.getDefaultState(), 2);
            world.setBlockState(pos.add(9, 3, 1), Blocks.NETHER_BRICK_FENCE.getDefaultState(), 2);
            world.setBlockState(pos.add(10, 3, 1), Blocks.NETHER_BRICK_FENCE.getDefaultState(), 2);
            world.setBlockState(pos.add(11, 3, 1), Blocks.FIRE.getDefaultState(), 2);
            world.setBlockState(pos.add(12, 3, 1), Blocks.NETHER_BRICK_FENCE.getDefaultState(), 2);
            world.setBlockState(pos.add(0, 3, 2), Blocks.NETHER_BRICK_FENCE.getDefaultState(), 2);
            world.setBlockState(pos.add(1, 3, 2), Blocks.NETHER_BRICK_FENCE.getDefaultState(), 2);
            world.setBlockState(pos.add(2, 3, 2), Blocks.AIR.getDefaultState(), 2);
            world.setBlockState(pos.add(3, 3, 2), Blocks.AIR.getDefaultState(), 2);
            world.setBlockState(pos.add(4, 3, 2), Blocks.AIR.getDefaultState(), 2);
            world.setBlockState(pos.add(5, 3, 2), Blocks.AIR.getDefaultState(), 2);
            world.setBlockState(pos.add(6, 3, 2), Blocks.AIR.getDefaultState(), 2);
            world.setBlockState(pos.add(7, 3, 2), Blocks.AIR.getDefaultState(), 2);
            world.setBlockState(pos.add(8, 3, 2), Blocks.AIR.getDefaultState(), 2);
            world.setBlockState(pos.add(9, 3, 2), Blocks.AIR.getDefaultState(), 2);
            world.setBlockState(pos.add(10, 3, 2), Blocks.AIR.getDefaultState(), 2);
            world.setBlockState(pos.add(11, 3, 2), Blocks.NETHER_BRICK_FENCE.getDefaultState(), 2);
            world.setBlockState(pos.add(12, 3, 2), Blocks.NETHER_BRICK_FENCE.getDefaultState(), 2);
            world.setBlockState(pos.add(0, 3, 3), Blocks.AIR.getDefaultState(), 2);
            world.setBlockState(pos.add(1, 3, 3), Blocks.NETHER_BRICK_FENCE.getDefaultState(), 2);
            world.setBlockState(pos.add(2, 3, 3), Blocks.AIR.getDefaultState(), 2);
            world.setBlockState(pos.add(3, 3, 3), Blocks.AIR.getDefaultState(), 2);
            world.setBlockState(pos.add(4, 3, 3), Blocks.AIR.getDefaultState(), 2);
            world.setBlockState(pos.add(5, 3, 3), Blocks.AIR.getDefaultState(), 2);
            world.setBlockState(pos.add(6, 3, 3), Blocks.AIR.getDefaultState(), 2);
            world.setBlockState(pos.add(7, 3, 3), Blocks.AIR.getDefaultState(), 2);
            world.setBlockState(pos.add(8, 3, 3), Blocks.AIR.getDefaultState(), 2);
            world.setBlockState(pos.add(9, 3, 3), Blocks.AIR.getDefaultState(), 2);
            world.setBlockState(pos.add(10, 3, 3), Blocks.AIR.getDefaultState(), 2);
            world.setBlockState(pos.add(11, 3, 3), Blocks.NETHER_BRICK_FENCE.getDefaultState(), 2);
            world.setBlockState(pos.add(12, 3, 3), Blocks.AIR.getDefaultState(), 2);
            world.setBlockState(pos.add(0, 3, 4), Blocks.AIR.getDefaultState(), 2);
            world.setBlockState(pos.add(1, 3, 4), Blocks.NETHER_BRICK_FENCE.getDefaultState(), 2);
            world.setBlockState(pos.add(2, 3, 4), Blocks.AIR.getDefaultState(), 2);
            world.setBlockState(pos.add(3, 3, 4), Blocks.AIR.getDefaultState(), 2);
            world.setBlockState(pos.add(4, 3, 4), Blocks.AIR.getDefaultState(), 2);
            world.setBlockState(pos.add(5, 3, 4), Blocks.AIR.getDefaultState(), 2);
            world.setBlockState(pos.add(6, 3, 4), Blocks.AIR.getDefaultState(), 2);
            world.setBlockState(pos.add(7, 3, 4), Blocks.AIR.getDefaultState(), 2);
            world.setBlockState(pos.add(8, 3, 4), Blocks.AIR.getDefaultState(), 2);
            world.setBlockState(pos.add(9, 3, 4), Blocks.AIR.getDefaultState(), 2);
            world.setBlockState(pos.add(10, 3, 4), Blocks.AIR.getDefaultState(), 2);
            world.setBlockState(pos.add(11, 3, 4), Blocks.NETHER_BRICK_FENCE.getDefaultState(), 2);
            world.setBlockState(pos.add(12, 3, 4), Blocks.AIR.getDefaultState(), 2);
            world.setBlockState(pos.add(0, 3, 5), Blocks.AIR.getDefaultState(), 2);
            world.setBlockState(pos.add(1, 3, 5), Blocks.NETHER_BRICK_FENCE.getDefaultState(), 2);
            world.setBlockState(pos.add(2, 3, 5), Blocks.AIR.getDefaultState(), 2);
            world.setBlockState(pos.add(3, 3, 5), Blocks.AIR.getDefaultState(), 2);
            world.setBlockState(pos.add(4, 3, 5), Blocks.AIR.getDefaultState(), 2);
            world.setBlockState(pos.add(5, 3, 5), Blocks.AIR.getDefaultState(), 2);
            world.setBlockState(pos.add(6, 3, 5), Blocks.AIR.getDefaultState(), 2);
            world.setBlockState(pos.add(7, 3, 5), Blocks.AIR.getDefaultState(), 2);
            world.setBlockState(pos.add(8, 3, 5), Blocks.AIR.getDefaultState(), 2);
            world.setBlockState(pos.add(9, 3, 5), Blocks.AIR.getDefaultState(), 2);
            world.setBlockState(pos.add(10, 3, 5), Blocks.AIR.getDefaultState(), 2);
            world.setBlockState(pos.add(11, 3, 5), Blocks.NETHER_BRICK_FENCE.getDefaultState(), 2);
            world.setBlockState(pos.add(12, 3, 5), Blocks.AIR.getDefaultState(), 2);
            world.setBlockState(pos.add(0, 3, 6), Blocks.AIR.getDefaultState(), 2);
            world.setBlockState(pos.add(1, 3, 6), Blocks.NETHER_BRICK_FENCE.getDefaultState(), 2);
            world.setBlockState(pos.add(2, 3, 6), Blocks.AIR.getDefaultState(), 2);
            world.setBlockState(pos.add(3, 3, 6), Blocks.AIR.getDefaultState(), 2);
            world.setBlockState(pos.add(4, 3, 6), Blocks.AIR.getDefaultState(), 2);
            world.setBlockState(pos.add(5, 3, 6), Blocks.AIR.getDefaultState(), 2);
            world.setBlockState(pos.add(6, 3, 6), Blocks.AIR.getDefaultState(), 2);
            world.setBlockState(pos.add(7, 3, 6), Blocks.AIR.getDefaultState(), 2);
            world.setBlockState(pos.add(8, 3, 6), Blocks.AIR.getDefaultState(), 2);
            world.setBlockState(pos.add(9, 3, 6), Blocks.AIR.getDefaultState(), 2);
            world.setBlockState(pos.add(10, 3, 6), Blocks.AIR.getDefaultState(), 2);
            world.setBlockState(pos.add(11, 3, 6), Blocks.NETHER_BRICK_FENCE.getDefaultState(), 2);
            world.setBlockState(pos.add(12, 3, 6), Blocks.AIR.getDefaultState(), 2);
            world.setBlockState(pos.add(0, 3, 7), Blocks.AIR.getDefaultState(), 2);
            world.setBlockState(pos.add(1, 3, 7), Blocks.NETHER_BRICK_FENCE.getDefaultState(), 2);
            world.setBlockState(pos.add(2, 3, 7), Blocks.AIR.getDefaultState(), 2);
            world.setBlockState(pos.add(3, 3, 7), Blocks.AIR.getDefaultState(), 2);
            world.setBlockState(pos.add(4, 3, 7), Blocks.AIR.getDefaultState(), 2);
            world.setBlockState(pos.add(5, 3, 7), Blocks.AIR.getDefaultState(), 2);
            world.setBlockState(pos.add(6, 3, 7), Blocks.AIR.getDefaultState(), 2);
            world.setBlockState(pos.add(7, 3, 7), Blocks.AIR.getDefaultState(), 2);
            world.setBlockState(pos.add(8, 3, 7), Blocks.AIR.getDefaultState(), 2);
            world.setBlockState(pos.add(9, 3, 7), Blocks.AIR.getDefaultState(), 2);
            world.setBlockState(pos.add(10, 3, 7), Blocks.AIR.getDefaultState(), 2);
            world.setBlockState(pos.add(11, 3, 7), Blocks.NETHER_BRICK_FENCE.getDefaultState(), 2);
            world.setBlockState(pos.add(12, 3, 7), Blocks.AIR.getDefaultState(), 2);
            world.setBlockState(pos.add(0, 3, 8), Blocks.AIR.getDefaultState(), 2);
            world.setBlockState(pos.add(1, 3, 8), Blocks.NETHER_BRICK_FENCE.getDefaultState(), 2);
            world.setBlockState(pos.add(2, 3, 8), Blocks.AIR.getDefaultState(), 2);
            world.setBlockState(pos.add(3, 3, 8), Blocks.AIR.getDefaultState(), 2);
            world.setBlockState(pos.add(4, 3, 8), Blocks.AIR.getDefaultState(), 2);
            world.setBlockState(pos.add(5, 3, 8), Blocks.AIR.getDefaultState(), 2);
            world.setBlockState(pos.add(6, 3, 8), Blocks.AIR.getDefaultState(), 2);
            world.setBlockState(pos.add(7, 3, 8), Blocks.AIR.getDefaultState(), 2);
            world.setBlockState(pos.add(8, 3, 8), Blocks.AIR.getDefaultState(), 2);
            world.setBlockState(pos.add(9, 3, 8), Blocks.AIR.getDefaultState(), 2);
            world.setBlockState(pos.add(10, 3, 8), Blocks.AIR.getDefaultState(), 2);
            world.setBlockState(pos.add(11, 3, 8), Blocks.NETHER_BRICK_FENCE.getDefaultState(), 2);
            world.setBlockState(pos.add(12, 3, 8), Blocks.AIR.getDefaultState(), 2);
            world.setBlockState(pos.add(0, 3, 9), Blocks.AIR.getDefaultState(), 2);
            world.setBlockState(pos.add(1, 3, 9), Blocks.NETHER_BRICK_FENCE.getDefaultState(), 2);
            world.setBlockState(pos.add(2, 3, 9), Blocks.AIR.getDefaultState(), 2);
            world.setBlockState(pos.add(3, 3, 9), Blocks.AIR.getDefaultState(), 2);
            world.setBlockState(pos.add(4, 3, 9), Blocks.AIR.getDefaultState(), 2);
            world.setBlockState(pos.add(5, 3, 9), Blocks.AIR.getDefaultState(), 2);
            world.setBlockState(pos.add(6, 3, 9), Blocks.AIR.getDefaultState(), 2);
            world.setBlockState(pos.add(7, 3, 9), Blocks.AIR.getDefaultState(), 2);
            world.setBlockState(pos.add(8, 3, 9), Blocks.AIR.getDefaultState(), 2);
            world.setBlockState(pos.add(9, 3, 9), Blocks.AIR.getDefaultState(), 2);
            world.setBlockState(pos.add(10, 3, 9), Blocks.AIR.getDefaultState(), 2);
            world.setBlockState(pos.add(11, 3, 9), Blocks.NETHER_BRICK_FENCE.getDefaultState(), 2);
            world.setBlockState(pos.add(12, 3, 9), Blocks.AIR.getDefaultState(), 2);
            world.setBlockState(pos.add(0, 3, 10), Blocks.NETHER_BRICK_FENCE.getDefaultState(), 2);
            world.setBlockState(pos.add(1, 3, 10), Blocks.NETHER_BRICK_FENCE.getDefaultState(), 2);
            world.setBlockState(pos.add(2, 3, 10), Blocks.AIR.getDefaultState(), 2);
            world.setBlockState(pos.add(3, 3, 10), Blocks.AIR.getDefaultState(), 2);
            world.setBlockState(pos.add(4, 3, 10), Blocks.AIR.getDefaultState(), 2);
            world.setBlockState(pos.add(5, 3, 10), Blocks.AIR.getDefaultState(), 2);
            world.setBlockState(pos.add(6, 3, 10), Blocks.AIR.getDefaultState(), 2);
            world.setBlockState(pos.add(7, 3, 10), Blocks.AIR.getDefaultState(), 2);
            world.setBlockState(pos.add(8, 3, 10), Blocks.AIR.getDefaultState(), 2);
            world.setBlockState(pos.add(9, 3, 10), Blocks.AIR.getDefaultState(), 2);
            world.setBlockState(pos.add(10, 3, 10), Blocks.AIR.getDefaultState(), 2);
            world.setBlockState(pos.add(11, 3, 10), Blocks.NETHER_BRICK_FENCE.getDefaultState(), 2);
            world.setBlockState(pos.add(12, 3, 10), Blocks.NETHER_BRICK_FENCE.getDefaultState(), 2);
            world.setBlockState(pos.add(0, 3, 11), Blocks.NETHER_BRICK_FENCE.getDefaultState(), 2);
            world.setBlockState(pos.add(1, 3, 11), Blocks.FIRE.getDefaultState(), 2);
            world.setBlockState(pos.add(2, 3, 11), Blocks.NETHER_BRICK_FENCE.getDefaultState(), 2);
            world.setBlockState(pos.add(3, 3, 11), Blocks.NETHER_BRICK_FENCE.getDefaultState(), 2);
            world.setBlockState(pos.add(4, 3, 11), Blocks.NETHER_BRICK_FENCE.getDefaultState(), 2);
            world.setBlockState(pos.add(5, 3, 11), Blocks.NETHER_BRICK_FENCE.getDefaultState(), 2);
            world.setBlockState(pos.add(6, 3, 11), Blocks.NETHER_BRICK_FENCE.getDefaultState(), 2);
            world.setBlockState(pos.add(7, 3, 11), Blocks.NETHER_BRICK_FENCE.getDefaultState(), 2);
            world.setBlockState(pos.add(8, 3, 11), Blocks.NETHER_BRICK_FENCE.getDefaultState(), 2);
            world.setBlockState(pos.add(9, 3, 11), Blocks.NETHER_BRICK_FENCE.getDefaultState(), 2);
            world.setBlockState(pos.add(10, 3, 11), Blocks.NETHER_BRICK_FENCE.getDefaultState(), 2);
            world.setBlockState(pos.add(11, 3, 11), Blocks.FIRE.getDefaultState(), 2);
            world.setBlockState(pos.add(12, 3, 11), Blocks.NETHER_BRICK_FENCE.getDefaultState(), 2);
            world.setBlockState(pos.add(0, 3, 12), Blocks.NETHER_BRICK_FENCE.getDefaultState(), 2);
            world.setBlockState(pos.add(1, 3, 12), Blocks.NETHER_BRICK_FENCE.getDefaultState(), 2);
            world.setBlockState(pos.add(2, 3, 12), Blocks.NETHER_BRICK_FENCE.getDefaultState(), 2);
            world.setBlockState(pos.add(3, 3, 12), Blocks.AIR.getDefaultState(), 2);
            world.setBlockState(pos.add(4, 3, 12), Blocks.AIR.getDefaultState(), 2);
            world.setBlockState(pos.add(5, 3, 12), Blocks.AIR.getDefaultState(), 2);
            world.setBlockState(pos.add(6, 3, 12), Blocks.AIR.getDefaultState(), 2);
            world.setBlockState(pos.add(7, 3, 12), Blocks.AIR.getDefaultState(), 2);
            world.setBlockState(pos.add(8, 3, 12), Blocks.AIR.getDefaultState(), 2);
            world.setBlockState(pos.add(9, 3, 12), Blocks.AIR.getDefaultState(), 2);
            world.setBlockState(pos.add(10, 3, 12), Blocks.NETHER_BRICK_FENCE.getDefaultState(), 2);
            world.setBlockState(pos.add(11, 3, 12), Blocks.NETHER_BRICK_FENCE.getDefaultState(), 2);
            world.setBlockState(pos.add(12, 3, 12), Blocks.NETHER_BRICK_FENCE.getDefaultState(), 2);

            return true;
        }

        return false;
    }

    private String pickRandomSpawner(Random rand)
    {
        return NetherExAPI.getRandomDungeonMob(rand);
    }
}